Workbook

Sheet Form Responses 1

Sheet Batteries
I1: Density | L1: Charge | N1: Discharge
C2: MJ / kg | I2: Wh / kg | J2: kWh / kg | L2: kcal / h | N2: kW / kg | Q2: kW
C3: Energy | D3: Charge | F3: Discharge | I3: Energy | J3: Useable | L3: Synthesis | M3: Eff | N3: Power | O3: Eff | Q3: Heat
B4: Li - Ion | C4: =J4*3600 / 1000 -> 0.9 | D4: =I4*3600/(N4*1000) / 60 * 1/O4 -> 16.666667 | E4: min | F4: =I4*3600/(N4*1000) / 60 * O4 -> 13.5 | G4: min | I4: 250 | J4: =I4/1000 -> 0.25 | N4: 1 | O4: 0.9 | Q4: =N4/O4*(1-O4) -> 0.11111111
B5: Solid state | C5: =J5*3600 / 1000 -> 1.8 | D5: =I5*3600/(N5*1000) / 60 * 1/O5 -> 16.666667 | E5: min | F5: =I5*3600/(N5*1000) / 60 * O5 -> 13.5 | G5: min | I5: 500 | J5: =I5/1000 -> 0.5 | N5: 2 | O5: 0.9 | Q5: =N5/O5*(1-O5) -> 0.22222222
A6: Bio | B6: Carbs | C6: =J6*3600 / 1000 -> 5.4 | D6: =(I6/1000)/(L6/860) * 1/M6 -> 23.888889 | E6: h | F6: =(I6/1000)/(N6/3600)/60*O6 -> 45 | G6: min | I6: 5000 | J6: =I6*O6/1000 -> 1.5 | L6: 200 | M6: 0.9 | N6: 2 | O6: 0.3 | Q6: =N6/O6*(1-O6) -> 4.6666667
A7: Bio | B7: Sugar cell (+) | C7: =J7*3600 / 1000 -> 10.8 | D7: =(I7/1000)/(L7/860) * 1/M7 -> 15.925926 | E7: h | F7: =(I7/1000)/(N7/3600)/60*O7 -> 18 | G7: min | I7: 5000 | J7: =I7*O7/1000 -> 3 | L7: 300 | M7: 0.9 | N7: 10 | O7: 0.6 | Q7: =N7/O7*(1-O7) -> 6.6666667
A8: Bio | B8: Graisse | C8: =J8*3600 / 1000 -> 10.8 | D8: =(I8/1000)/(L8/860) * 1/M8 -> 35.833333 | E8: h | F8: =(I8/1000)/(N8/3600)/3600*O8 -> 60 | G8: h | I8: 10000 | J8: =I8*O8/1000 -> 3 | L8: 300 | M8: 0.8 | N8: 0.05 | O8: 0.3 | Q8: =N8/O8*(1-O8) -> 0.11666667
A9: Bio | B9: Fat cell (+) | C9: =J9*3600 / 1000 -> 21.6 | D9: =(I9/1000)/(L9/860) * 1/M9 -> 19.111111 | E9: h | F9: =(I9/1000)/(N9/3600)/3600*O9 -> 6 | G9: h | I9: 10000 | J9: =I9*O9/1000 -> 6 | L9: 500 | M9: 0.9 | N9: 1 | O9: 0.6 | Q9: =N9/O9*(1-O9) -> 0.66666667
B10: Graphene | C10: =J10*3600 / 1000 -> 0.36 | D10: =I10*3600/(N10*1000) * 1/O10 -> 4 | E10: sec | F10: =I10*3600/(N10*1000) * O10 -> 3.24 | G10: sec | I10: 100 | J10: =I10/1000 -> 0.1 | M10: 0.9 | N10: 100 | O10: 0.9 | Q10: 0
B11: RTG (Voyager) | C11: =J11*3600 / 1000 -> 18 | D11: - | I11: 10000 | J11: =I11/2000 -> 5 | N11: 1e-06 | O11: 1
B12: Tritium | C12: =J12*3600 / 1000 -> 1800000 | D12: - | F12: 10 | G12: ans | I12: 1000000000 | J12: =I12/2000 -> 500000 | N12: 0.001 | O12: 1
B13: Nickel 63 | C13: =J13*3600 / 1000 -> 1800 | D13: - | F13: 50 | G13: ans | I13: 1000000 | J13: =I13/2000 -> 500 | N13: 1e-06 | O13: 1
B14: Carbon 14 | C14: =J14*3600 / 1000 -> 1800 | D14: - | F14: 2000 | G14: ans | I14: 1000000 | J14: =I14/2000 -> 500 | N14: 1e-09 | O14: 1
B15: Li - Air | C15: =J15*3600 / 1000 -> 5.04 | D15: - | F15: =I15*3600/(N15*1000) / 3600 * 1/O15 -> 1.4285714 | G15: h | I15: 2000 | J15: =I15*O15/1000 -> 1.4 | N15: 2 | O15: 0.7

Sheet Sheet46
B3: Activity | C3: Metabolic power (W) | D3: Mechanical power (W) | E3: Implied efficiency
B4: Rest / quiet sitting | C4: 80 – 120 W | D4: ~5 – 20 W (postural) | E4: ~5–20% (very low useful work)
B5: Standing (light activity) | C5: 120 – 180 W | D5: 20 – 50 W | E5: ~15–30%
B6: Walking (5 km/h) | C6: 200 – 350 W | D6: 60 – 120 W | E6: ~20–35%
B7: Brisk walk / power walk | C7: 300 – 450 W | D7: 80 – 150 W | E7: ~25–35%
B8: Easy jogging (8 km/h) | C8: 500 – 700 W | D8: 150 – 250 W | E8: ~25–35%
B9: Steady run (10 km/h) | C9: 700 – 900 W | D9: 200 – 350 W | E9: ~25–35%
B10: Marathon pace (elite ~20 km/h unrealistic; typical marathon pace) | C10: 600 – 900 W (sustained hours) | D10: 150 – 300 W | E10: ~25–35%
B11: Hard run / threshold (race pace) | C11: 900 – 1,500 W | D11: 250 – 500 W | E11: ~25–35%
B12: All-out sprint (100 m, elite) | C12: 2,000 – 6,000 W (short, seconds) | D12: 500 – 1,500 W | E12: ~~20–30% (mechanical peak may be higher for limbs)
B13: Short explosive burst (single jump, lift) | C13: 1,000 – 10,000 W (very short) | D13: 200 – 3,000 W (depending on task) | E13: highly variable
B14: Max instantaneous leg muscle power (elite) | C14: — (metabolic supplied from ATP/PCr + glycolysis) | D14: ~1,000–3,000 W (legs peak, for <1 s) | E14: n/a (burst systems + elastic storage)

Sheet Augments 2
U1: Battery | AA1: Density
G2: time | J2: km/h | K2: degats | M2: kN/kg | N2: kW/kg | O2: kW / kg | P2: kg | Q2: %total | R2: MW | S2: MW | U2: kg | V2: MJ | W2: sec | X2: kg | Y2: %total | AA2: MJ / kg | AB2: kW / kg
B3: Corps | D3: Indice | E3: Cout | G3: Battery | H3: Load | J3: Sprint | K3: Punch | M3: Strength | N3: Power | O3: Heat | P3: Mass | Q3: Muscle | R3: Power | S3: Heat | U3: Mass | V3: Energy | W3: Time | X3: Water | Y3: Mass | Z3: Eff | AA3: Energy | AB3: Power
B4: Bio | C4: Standard | D4: 3 | E4: 0 | G4: 30 | H4: x 1 | J4: 20 | K4: 0+ | M4: 1 | N4: 1 | O4: =N4/0.3 * (0.7) -> 2.3333333 | P4: 70 | Q4: 0.3 | R4: =N4*P4*Q4/1000 / Z4 -> 0.07 | S4: =O4*P4*Q4/1000 -> 0.049 | U4: 0.5 | V4: =U4*AA4 -> 2.5 | W4: =V4/R4 -> 35.714286 | X4: =S4/2.5*W4 -> 0.7 | Y4: =(U4+X4)/P4 *100*1.15 -> 1.9714286 | Z4: 0.3 | AA4: 5 | AB4: 1
B5: Bio | C5: Athlétique | D5: 4 | E5: 2 | G5: 45 | H5: x 3 | J5: 35 | K5: 0+ | M5: 1.5 | N5: 2 | O5: =N5/0.3 * (0.7) -> 4.6666667 | P5: 80 | Q5: 0.4 | R5: =N5*P5*Q5/1000 / Z5 -> 0.21333333 | S5: =O5*P5*Q5/1000 -> 0.14933333 | U5: 2 | V5: =U5*AA5 -> 10 | W5: =V5/R5 -> 46.875 | X5: =S5/2.5*W5 -> 2.8 | Y5: =(U5+X5)/P5 *100*1.15 -> 6.9 | Z5: 0.3 | AA5: 5 | AB5: 2
B6: Bio | C6: Transhumain | D6: 5 | E6: 5 | G6: 60 | H6: x 5 | J6: 70 | K6: 1+ | M6: 3 | N6: 10 | O6: =N6/0.6 * (0.4) -> 6.6666667 | P6: 90 | Q6: 0.5 | R6: =N6*P6*Q6/ 1000 / Z6 -> 0.75 | S6: =O6*P6*Q6/1000 -> 0.3 | U6: 4 | V6: =U6*AA6 -> 40 | W6: =V6/R6 -> 53.333333 | X6: =S6/2.5*W6 -> 6.4 | Y6: =(U6+X6)/P6 *100*1.15 -> 13.288889 | Z6: 0.6 | AA6: 10 | AB6: 10
C7: Metahumain | D7: 6 | E7: 10 | G7: 20 | H7: x 10 | J7: 100 | K7: 2+ | M7: 10 | N7: 50 | O7: =N7/0.6 * (0.4) -> 33.333333 | P7: 100 | Q7: 0.5 | R7: =N7*P7*Q7/1000 / Z7 -> 4.1666667 | S7: =O7*P7*Q7/1000 -> 1.6666667 | U7: 8 | V7: =U7*AA7 -> 80 | W7: =V7/R7 -> 19.2 | X7: =S7/2.5*W7 -> 12.8 | Y7: =(U7+X7)/P7 *100*1.15 -> 23.92 | Z7: 0.6 | AA7: 10 | AB7: 10
G9: minutes | H9: kg | L9: Flops | N9: W/kg | O9: W | P9: %total | Q9: MJ | R9: MW
B10: Processeur | D10: Indice | E10: Cout | G10: Battery | H10: Mass | J10: Ref | L10: Perf | N10: Power | O10: Power | P10: Battery | Q10: Energy | R10: Heat
C11: Free | D11: 3 | E11: 0 | G11: =Q11*10^6/O11/60 -> 200 | H11: 0.1 | J11: Smartphone | L11: e11 | N11: 50 | O11: =N11*H11 -> 5 | P11: 0.3 | Q11: =H11*2*P11 -> 0.06 | R11: =O11*10^-6 -> 5e-06
C12: Pro | D12: 4 | E12: 2 | G12: =Q12*10^6/O12/60 -> 100 | H12: 1 | J12: Laptop | L12: e12 | N12: 50 | O12: =N12*H12 -> 50 | P12: 0.15 | Q12: =H12*2*P12 -> 0.3 | R12: =O12*10^-6 -> 5e-05
C13: Gamer | D13: 5 | E13: 5 | G13: =Q13*10^6/O13/60 -> 30 | H13: 10 | J13: Gaming laptop | L13: e13 | N13: 100 | O13: =N13*H13 -> 1000 | P13: 0.09 | Q13: =H13*2*P13 -> 1.8 | R13: =O13*10^-6 -> 0.001
C14: Hacker | D14: 6 | E14: 10 | G14: =Q14*10^6/O14/60 -> 5 | H14: 50 | J14: Custom rig | L14: e14 | N14: 600 | O14: =N14*H14 -> 30000 | P14: 0.09 | Q14: =H14*2*P14 -> 9 | R14: =O14*10^-6 -> 0.03
C15: Maison | D15: 3+2D | E15: 2 | H15: 10 | J15: Desktop | L15: e13 | N15: 50 | O15: 1000 | R15: =O15*10^-6 -> 0.001
C16: Magasin | D16: 4+2D | E16: 4 | H16: 100 | L16: e14 | N16: 50 | O16: 10000 | R16: =O16*10^-6 -> 0.01
C17: Serveur | D17: 5+3D | E17: 8 | H17: 10 ton | N17: 100 | O17: 1000000 | R17: =O17*10^-6 -> 1
C18: Mainframe | D18: 6+4D | E18: 14 | H18: 500 ton | J18: Supercomputer | L18: e18 | N18: 600 | O18: 100000000 | R18: =O18*10^-6 -> 100
C19: Oversize | D19: +1D | E19: +1 | G19: = | H19: x 10 | L19: x 10 | N19: x 10 | O19: x 10 | R19: x 10
C20: Miniaturized | D20: -1D | E20: +1 | G20: = | H20: / 10 | L20: / 10 | N20: / 10 | O20: / 10 | R20: / 10
G22: kg | H22: % / sec | I22: kg | K22: g | L22: g | M22: m/s
B23: Jambes | D23: Indice | E23: Cout | G23: Masse | H23: Power | I23: Load | K23: Sprint | L23: Jump | M23: Speed | P23: Taille | Q23: Mass | R23: Load | S23: Scale
C24: Standard | D24: 3 | E24: 0 | G24: 30 | H24: 0 | I24: x 1 | K24: 0.5 | L24: 2 | M24: 5 | P24: -4 | Q24: 1 g | R24: 50 g | S24: x 50
C25: Athlétique | D25: 4 | E25: 0 | G25: 40 | H25: 0 | I25: x 3 | K25: 1 | L25: 3 | M25: 10 | P25: -3 | Q25: 100 g | R25: 1 kg | S25: x 10
C26: Transhumain | D26: 5 | E26: 1 | G26: 40 | H26: 1 | I26: x 5 | K26: 2 | L26: 5 | M26: 20 | P26: -2 | Q26: 1 kg | R26: 5 kg | S26: x 5
C27: Metahumain | D27: 6 | E27: 2 | G27: 40 | H27: 5 | I27: x 10 | K27: 5 | L27: 10 | M27: 40 | P27: -1 | Q27: 10 kg | R27: 20 kg | S27: x 2
C28: Speedrun | D28: 6 | E28: 3 | G28: 40 | H28: 5 | I28: x 1 | K28: 10 | L28: 5 | M28: 100 | P28: 0 | Q28: 100 kg | R28: 100 kg | S28: x 1
B29: Bio | C29: Cricket | P29: 1 | Q29: 1 t | R29: 500 kg | S29: / 2
C30: Spring | D30: 6 | E30: 3 | G30: 20 | H30: 5 | I30: x 1 | K30: 1 | L30: 20 | M30: 100 | P30: 2 | Q30: 10 t | R30: 2 t | S30: / 5
B31: Bio | C31: Cheetah | D31: 5 | E31: 1 | G31: 30 | H31: 0 | K31: 1 | L31: 5 | M31: 30 | P31: 3 | Q31: 100 t | R31: 10 t | S31: / 10
C32: Roues | E32: 0 | G32: 20 | H32: 1 | I32: x10 | K32: 1 | L32: 0 | M32: 100
C33: Chenilles | E33: 0 | G33: 20 | H33: 1 | I33: x100 | K33: 1 | L33: 0 | M33: 20
B34: Bio | C34: Spider | E34: 1 | H34: 0
E36: %corps | G36: % / sec | J36: degats | L36: m/s | M36: kJ
B37: Bras | D37: Cout | E37: Masse | G37: Power | H37: Lift | J37: Melee | L37: Swing | M37: Punch
C38: Standard | D38: 0 | E38: 3 | G38: 0 | H38: x 1 | J38: 0+ | L38: 10 | M38: 0.2
C39: Athlétique | D39: 0 | E39: 5 | G39: 0 | H39: x 3 | J39: 0+ | L39: 20 | M39: 1
C40: Transhumain | D40: 0 | E40: 10 | G40: 1 | H40: x 5 | J40: 1+ | L40: 50 | M40: 5
C41: Metahumain | D41: 1 | E41: 10 | G41: 2 | H41: x 10 | J41: 2+ | L41: 100 | M41: 50
B42: Bio | C42: Gorille | D42: 1 | E42: 20 | G42: 0 | H42: x 20 | J42: 1+ | L42: 20 | M42: 5
C43: Gunslinger | D43: 3 | E43: 10 | G43: 1 | H43: x 1 | J43: 0+ | L43: 10 | M43: 0.5
...

Sheet Engines
C1: GW | D1: km/s | E1: kN | F1: kg/sec | G1: t | H1: kN / kg | I1: GW / t | K1: t | L1: g
C2: Power | D2: Ve | E2: Thrust | F2: Fuel | G2: Mass | H2: T / m | I2: P / m | K2: ship | L2: accel
B3: Supersonic jet | C3: 0.03 | D3: 1 | E3: 100 | F3: 150 | G3: 1 | H3: =E3/G3/1000 -> 0.1 | I3: =C3/G3 -> 0.03 | K3: 3 | L3: =E3/K3/10 -> 3.3333333
B4: Merlin 1D | C4: 2600 | D4: 3 | E4: =2*C4/D4*O4 -> 936 | F4: 274 | G4: 0.5 | H4: =E4/G4/1000 -> 1.872 | I4: =C4/G4 -> 5200 | K4: =G4*10 -> 5 | L4: =E4/K4/10 -> 18.72 | N4: n | O4: 0.54
B5: Raptor 2 | C5: 8000 | D5: 3.5 | E5: 2300 | F5: 705 | G5: 1.6 | H5: =E5/G5/1000 -> 1.4375 | I5: =C5/G5 -> 5000 | K5: =G5*10 -> 16 | L5: =E5/K5/10 -> 14.375
B6: Saturn V | C6: 20000 | D6: 2.5 | E6: 7740 | G6: 8.4 | H6: =E6/G6/1000 -> 0.92142857 | I6: =C6/G6 -> 2380.9524 | K6: =G6*10 -> 84 | L6: =E6/K6/10 -> 9.2142857
B7: MICFAM MH 1 | C7: 100 | D7: 400 | E7: 500 | F7: 2.2 | G7: 1 | H7: =E7/G7/1000 -> 0.5 | I7: =C7/G7 -> 100 | K7: =G7*10 -> 10 | L7: =E7/K7/10 -> 5
B8: MICFAM MH 2 | C8: 100 | D8: 200 | E8: 1000 | F8: 5 | G8: 1 | H8: =E8/G8/1000 -> 1 | I8: =C8/G8 -> 100 | K8: =G8*10 -> 10 | L8: =E8/K8/10 -> 10
B9: MICFAM MH 3 | C9: 100 | D9: 100 | E9: 2000 | F9: 20 | G9: 1 | H9: =E9/G9/1000 -> 2 | I9: =C9/G9 -> 100 | K9: =G9*10 -> 10 | L9: =E9/K9/10 -> 20
B10: MICFAM Cruise | C10: 100 | D10: 11000 | E10: =2*C10*1000/D10 -> 18.181818 | F10: =E10/D10 -> 0.0016528926 | G10: 1 | H10: =E10/G10/1000 -> 0.018181818 | I10: =C10/G10 -> 100 | K10: =G10*10 -> 10 | L10: =E10/K10/10 -> 0.18181818
B11: Epstein | C11: 5500 | D11: 11000 | E11: =2*C11*1000/D11 -> 1000 | F11: =E11/D11 -> 0.090909091 | G11: =C11/100 -> 55 | H11: =E11/G11/1000 -> 0.018181818 | I11: =C11/G11 -> 100 | K11: =G11*10 -> 550 | L11: =E11/K11/10 -> 0.18181818
B12: Booster DDE | C12: =G12*5000 -> 125 | D12: 5 | E12: =2*C12/D12*O12 -> 50 | F12: =E12/D12 -> 10 | G12: 0.025 | H12: =E12/G12/1000 -> 2 | I12: =C12/G12 -> 5000 | K12: 0.1 | L12: =E12/K12/10 -> 50 | N12: n | O12: 1
B13: Jet suit | C13: 0.0008 | E13: 1.4 | F13: =0.832/60*1.5 -> 0.0208 | G13: 0.0025 | H13: =E13/G13/1000 -> 0.56 | I13: =C13/G13 -> 0.32 | K13: 0.1 | L13: =E13/K13/10 -> 1.4
J15: Mass ratio | K15: 2 | M15: Wet mass | N15: 100 | P15: t
H16: kN / kg
B17: Gen T | C17: Tp (TW) | D17: Ve (km/s) | E17: T (kN) | F17: Fuel | G17: Mass (t) | H17: T / m | J17: dV (km/s) | K17: dV (c) | M17: accel (g) | P17: Horse power
B18: AM Beam MAX | C18: 500 | D18: 100000 | E18: 10000 | F18: D+A | G18: 10 | H18: =E18/G18 -> 1000 | J18: =$D18*LN($K$15) -> 69314.718 | K18: =$D18*LN($K$15)*1000/299792458 -> 0.23120901 | M18: =E18/$N$15/10 -> 10 | P18: =C18*1000000000/735 -> 6.8027211e+08
A19: =D19*E19/2/1000000 -> 500 | B19: ICF MAX | C19: 500 | D19: 10000 | E19: 100000 | F19: P | G19: 1000 | H19: =E19/G19 -> 100 | J19: =$D19*LN($K$15) -> 6931.4718 | K19: =$D19*LN($K$15)*1000/299792458 -> 0.023120901 | M19: =E19/$N$15/10 -> 100 | P19: =C19*1000000000/735 -> 6.8027211e+08
B20: Low gear | D20: 20000 | E20: 50000 | F20: P+H | H20: =E20/G20 -> #DIV/0! | J20: =$D20*LN($K$15) -> 13862.944 | K20: =$D20*LN($K$15)*1000/299792458 -> 0.046241802 | M20: =E20/$N$15/10 -> 50 | P20: =C20*1000000000/735 -> 0
B21: NSWR MAX | C21: 30 | D21: 4700 | E21: 13000 | F21: U | H21: =E21/G21 -> #DIV/0! | J21: =$D21*LN($K$15) -> 3257.7917 | K21: =$D21*LN($K$15)*1000/299792458 -> 0.010866824 | M21: =E21/$N$15/10 -> 13 | P21: =C21*1000000000/735 -> 40816327
B22: Orion MAX | C22: 39 | D22: 9800 | E22: 8000 | F22: P | G22: 8 | H22: =E22/G22 -> 1000 | J22: =$D22*LN($K$15) -> 6792.8424 | K22: =$D22*LN($K$15)*1000/299792458 -> 0.022658483 | M22: =E22/$N$15/10 -> 8 | P22: =C22*1000000000/735 -> 53061224
B23: ICF Exacting | C23: 10 | D23: 7000 | E23: =2*C23*1000000/D23 -> 2857.1429 | F23: P | G23: =C23/3 -> 3.3333333 | H23: =E23/G23 -> 857.14286 | J23: =$D23*LN($K$15) -> 4852.0303 | K23: =$D23*LN($K$15)*1000/299792458 -> 0.016184631 | M23: =E23/$N$15/10 -> 2.8571429 | P23: =C23*1000000000/735 -> 13605442
B24: Low gear | D24: 20000 | E24: 1050 | F24: P+H | H24: =E24/G24 -> #DIV/0! | J24: =$D24*LN($K$15) -> 13862.944 | K24: =$D24*LN($K$15)*1000/299792458 -> 0.046241802 | M24: =E24/$N$15/10 -> 1.05 | P24: =C24*1000000000/735 -> 0 | S24: =3000/40 -> 75 | T24: =3/40 -> 0.075
B25: ICF Stratios | C25: 42 | D25: 7000 | E25: =2*C25*1000000/D25 -> 12000 | F25: P | G25: =C25/3 -> 14 | H25: =E25/G25 -> 857.14286 | J25: =$D25*LN($K$15) -> 4852.0303 | K25: =$D25*LN($K$15)*1000/299792458 -> 0.016184631 | M25: =E25/$N$15/10 -> 12 | N25: 13h | P25: =C25*1000000000/735 -> 57142857
B26: Low gear | D26: 20000 | E26: =2*C25*1000000/D26 -> 4200 | F26: P+H | H26: =E26/G26 -> #DIV/0! | J26: =$D26*LN($K$15) -> 13862.944 | K26: =$D26*LN($K$15)*1000/299792458 -> 0.046241802 | M26: =E26/$N$15/10 -> 4.2 | P26: =C26*1000000000/735 -> 0
B27: AM Beam Stratios | C27: =D27*E27/2/1000000 -> 75 | D27: 50000 | E27: 3000 | F27: D+A | G27: 10 | H27: =E27/G27 -> 300 | J27: =$D27*LN($K$15) -> 34657.359 | K27: =$D27*LN($K$15)*1000/299792458 -> 0.11560451 | M27: =E27/$N$15/10 -> 3 | P27: =C27*1000000000/735 -> 1.0204082e+08
B28: ICF Nestor | C28: =D28*E28/2/1000000 -> 350 | D28: 7000 | E28: 100000 | F28: P | G28: =C28/3 -> 116.66667 | H28: =E28/G28 -> 857.14286 | J28: =$D28*LN($K$15) -> 4852.0303 | K28: =$D28*LN($K$15)*1000/299792458 -> 0.016184631 | M28: =E28/$N$15/10 -> 100 | N28: 13h | P28: =C28*1000000000/735 -> 4.7619048e+08
B29: Firefly | C29: 12 | D29: 12890 | E29: 1900 | H29: =E29/G29 -> #DIV/0! | J29: =$D29*LN($K$15) -> 8934.6672 | K29: =$D29*LN($K$15)*1000/299792458 -> 0.029802842 | M29: =E29/$N$15/10 -> 1.9 | P29: =C29*1000000000/735 -> 16326531
B30: Epstein | C30: 5.5 | D30: 11000 | E30: =2*C30*1000000/D30 -> 1000 | F30: D+T | G30: =C30/3 -> 1.8333333 | H30: =E30/G30 -> 545.45455 | J30: =$D30*LN($K$15) -> 7624.619 | K30: =$D30*LN($K$15)*1000/299792458 -> 0.025432991 | M30: =E30/$N$15/10 -> 1 | P30: =C30*1000000000/735 -> 7482993.2
B31: Epstein 2 | C31: 100 | D31: 19000 | E31: =2*C31*1000000/D31 -> 10526.316 | G31: =C31/3 -> 33.333333 | H31: =E31/G31 -> 315.78947
B32: AV:T | D32: 1000 | F32: D+H | H32: =E32/G32 -> #DIV/0! | J32: =$D32*LN($K$15) -> 693.14718 | K32: =$D32*LN($K$15)*1000/299792458 -> 0.0023120901 | M32: =E32/$N$15/10 -> 0 | P32: =C32*1000000000/735 -> 0
B33: Cruise | C33: 0.1 | E33: 245 | H33: =E33/G33 -> #DIV/0! | J33: =$D33*LN($K$15) -> 0 | K33: =$D33*LN($K$15)*1000/299792458 -> 0 | M33: =E33/$N$15/10 -> 0.245 | P33: =C33*1000000000/735 -> 136054.42
B34: Combat | C34: 2.5 | E34: 50000 | H34: =E34/G34 -> #DIV/0! | J34: =$D34*LN($K$15) -> 0 | K34: =$D34*LN($K$15)*1000/299792458 -> 0 | M34: =E34/$N$15/10 -> 50 | P34: =C34*1000000000/735 -> 3401360.5
B35: MI Fusion Icarus | C35: 8 | D35: 8922 | E35: =1.78*1000 -> 1780 | F35: D | H35: =E35/G35 -> #DIV/0! | J35: =$D35*LN($K$15) -> 6184.2591 | K35: =$D35*LN($K$15)*1000/299792458 -> 0.020628468 | M35: =E35/$N$15/10 -> 1.78 | P35: =C35*1000000000/735 -> 10884354
B36: Orion MAX | C36: 39 | D36: 9800 | E36: 8000 | F36: P | G36: 10 | H36: =E36/G36 -> 800 | J36: =$D36*LN($K$15) -> 6792.8424 | K36: =$D36*LN($K$15)*1000/299792458 -> 0.022658483 | M36: =E36/$N$15/10 -> 8 | P36: =C36*1000000000/735 -> 53061224
B37: Orion 10k | C37: 24 | D37: 120 | E37: 400000 | F37: D | G37: 3250 | H37: =E37/G37 -> 123.07692 | J37: =$D37*LN($K$15) -> 83.177662 | K37: =$D37*LN($K$15)*1000/299792458 -> 0.00027745081 | M37: =E37/$N$15/10 -> 400 | P37: =C37*1000000000/735 -> 32653061
B38: Orion 4k | C38: 1.6 | D38: 39 | E38: 80000 | F38: D | G38: 1700 | H38: =E38/G38 -> 47.058824 | J38: =$D38*LN($K$15) -> 27.03274 | K38: =$D38*LN($K$15)*1000/299792458 -> 9.0171515e-05 | M38: =E38/$N$15/10 -> 80 | P38: =C38*1000000000/735 -> 2176870.7
B39: Orion USAF | C39: 33 | D39: 33 | E39: 2000 | F39: D | G39: 3250 | H39: =E39/G39 -> 0.61538462 | J39: =$D39*LN($K$15) -> 22.873857 | K39: =$D39*LN($K$15)*1000/299792458 -> 7.6298974e-05 | M39: =E39/$N$15/10 -> 2 | P39: =C39*1000000000/735 -> 44897959
B40: Orion Fusion | C40: 10.7 | D40: 73 | E40: 292 | F40: D | G40: 200 | H40: =E40/G40 -> 1.46 | J40: =$D40*LN($K$15) -> 50.599744 | K40: =$D40*LN($K$15)*1000/299792458 -> 0.00016878258 | M40: =E40/$N$15/10 -> 0.292 | P40: =C40*1000000000/735 -> 14557823
B41: Orion Fission | C41: 5.7 | D41: 43 | E41: 263 | F41: U | H41: =E41/G41 -> #DIV/0! | J41: =$D41*LN($K$15) -> 29.805329 | K41: =$D41*LN($K$15)*1000/299792458 -> 9.9419875e-05 | M41: =E41/$N$15/10 -> 0.263 | P41: =C41*1000000000/735 -> 7755102
...

Sheet MICFAM
B2: =1/500 -> 0.002
C4: F=ve​P​=1.5×1053.8×1012​=25.3×106N=25.3MN
C5: a=mF​=300,00025.3×106​=84.3m/s2≈8.6g
A8: COMBAT MODE | L8: FOR 10 SECONDS BURST
B9: Power | C9: P | D9: 5 | E9: TW | F9: =D9*10^12 -> 5000000000000 | H9: MICFAM | I9: 100 | J9: MW/kg | K9: Engine | M9: Thrust | O9: Delta v | Q9: Heatsink | S9: Fuel | U9: Delta v | W9: Heat | Y9: Fuel
B10: Exhaust velocity | C10: Ve | D10: 400 | E10: kms | F10: =D10*10^3 -> 400000 | I10: =I9/1000 -> 0.1 | J10: TW/t | M10: 10 | N10: g | O10: 10 | P10: km/r | Q10: 15 | R10: % | S10: 15 | T10: % | U10: 1 | V10: km/s | W10: 1 | X10: TJ | Y10: 2 | AA10: t
B11: Nozzle eff | C11: n | D11: 0.99 | E11: ratio | I11: =D9*10 -> 50 | J11: t | M11: 5 | N11: g | O11: =$M11/$M$10*O$10 -> 5 | P11: km/r | Q11: =$M11/$M$10*Q$10 -> 7.5 | R11: % | S11: =$M11/$M$10*S$10 -> 7.5 | T11: % | U11: =$M11/$M$10*U$10 -> 0.5 | W11: =$M11/$M$10*W$10 -> 0.5 | Y11: =$M11/$M$10*Y$10 -> 1
A12: F = 2Pn / Ve | B12: Thrust | C12: F | D12: =2*F9*D11/F10*10^-6 -> 24.75 | E12: MN | M12: 2 | N12: g | O12: =$M12/$M$10*O$10 -> 2 | P12: km/r | Q12: =$M12/$M$10*Q$10 -> 3 | R12: % | S12: =$M12/$M$10*S$10 -> 3 | T12: % | U12: =$M12/$M$10*U$10 -> 0.2 | W12: =$M12/$M$10*W$10 -> 0.2 | Y12: =$M12/$M$10*Y$10 -> 0.4
B13: Ship mass | C13: m | D13: 500 | E13: t | H13: MH | I13: 15 | J13: t | M13: 1 | N13: g | O13: =$M13/$M$10*O$10 -> 1 | P13: km/r | Q13: =$M13/$M$10*Q$10 -> 1.5 | R13: % | S13: =$M13/$M$10*S$10 -> 1.5 | T13: % | U13: =$M13/$M$10*U$10 -> 0.1 | W13: =$M13/$M$10*W$10 -> 0.1 | Y13: =$M13/$M$10*Y$10 -> 0.2
B14: Acceleration | C14: a | D14: =F14/9.81 -> 5.0458716 | E14: g | F14: =D12*10^6/(D13*10^3) -> 49.5 | G14: m/s² | H14: LiH | I14: 10 | J14: t | K14: Heat sink
F15: =5*550/D13*D9/4 -> 6.875 | I15: 20 | J15: MJ / kg
A16: m = F / Ve | B16: Mass flow | C16: m | D16: =(D12*10^6)/(D10*10^3) -> 61.875 | E16: kg/s | I16: =(I14*10^3)*I15*10^-6 -> 0.2 | J16: TJ
B17: Brayton cycle | D17: 35 | E17: %
B18: Waste heat | C18: h | D18: =D9*(1-D11)* (100-D17)/100 * 10^3 -> 32.5 | E18: GW = GJ/s | F18: =D21/D9 -> 0.12375
H19: ETHER | I19: 1 | J19: t | K19: Radiator
B20: burn time | C20: t | D20: 10 | E20: s | F20: =F14*D20/1000 -> 0.495 | G20: km/s | I20: 200 | J20: MW/t
B21: fuel used | C21: m | D21: =D16*D20*10^-3 -> 0.61875 | E21: t | F21: =D21/I13*100 -> 4.125 | G21: % fuel tank | I21: =I19*I20 -> 200 | J21: MW
B22: waste heat | C22: h | D22: =D18*D20*10^-3 -> 0.325 | E22: TJ | F22: =D22/I16*100 -> 162.5 | G22: % of heat sink | I22: =I21*10^-3 -> 0.2 | J22: GW
B23: speed | C23: delta v | D23: =F14*10^-3*D20 -> 0.495 | E23: km/s | I23: =I22*10^-3 -> 0.0002 | J23: TW
B24: displacement | C24: d | D24: =1/2 * F14* D20^2 * 10^-3 -> 2.475 | E24: km
I25: =I22*540 -> 108
A27: CRUISE MODE
B28: Power | C28: P | D28: 5 | E28: TW | F28: =D28*10^12 -> 5000000000000 | H28: =60*60*24 -> 86400 | J28: =D28/D32*30 -> 0.3
B29: Exhaust velocity | C29: Ve | D29: 10000 | E29: kms | F29: =D29*10^3 -> 10000000 | H29: D | I29: 25 | J29: t | Q29: AU | R29: 0.1 | S29: 1 | T29: 2 | U29: 3 | V29: 4 | W29: 5 | X29: 10 | Y29: 15 | Z29: 20
B30: Nozzle eff | C30: n | D30: 0.99 | E30: ratio | L30: Accel phase | N30: 10 | O30: j | R30: =2* sqrt(R29*1.496*10^11 / ($F$33)) / 86400 -> 2.0120995 | S30: =2* sqrt(S29*1.496*10^11 / ($F$33)) / 86400 -> 6.3628173 | T30: =2* sqrt(T29*1.496*10^11 / ($F$33)) / 86400 -> 8.9983826 | U30: =2* sqrt(U29*1.496*10^11 / ($F$33)) / 86400 -> 11.020723 | V30: =2* sqrt(V29*1.496*10^11 / ($F$33)) / 86400 -> 12.725635 | W30: =2* sqrt(W29*1.496*10^11 / ($F$33)) / 86400 -> 14.227692 | X30: =2* sqrt(X29*1.496*10^11 / ($F$33)) / 86400 -> 20.120995 | Y30: =2* sqrt(Y29*1.496*10^11 / ($F$33)) / 86400 -> 24.643086 | Z30: =2* sqrt(Z29*1.496*10^11 / ($F$33)) / 86400 -> 28.455384 | AA30: d
A31: F = 2Pn / Ve | B31: Thrust | C31: F | D31: =2*F28*D30/F29*10^-6 -> 0.99 | E31: MN | I31: 0.5 | J31: g | L31: delta v | N31: =F34*N30 -> 1710.72 | O31: km/s | R31: =$G$35*R30 -> 17.210694 | S31: =$G$35*S30 -> 54.424994 | T31: =$G$35*T30 -> 76.968565 | U31: =$G$35*U30 -> 94.266855 | V31: =$G$35*V30 -> 108.84999 | W31: =$G$35*W30 -> 121.69799 | X31: =$G$35*X30 -> 172.10694 | Y31: =$G$35*Y30 -> 210.7871 | Z31: =$G$35*Z30 -> 243.39597 | AA31: % fuel
B32: Ship mass | C32: m | D32: 500 | E32: t | I32: =I31*10 -> 5 | J32: m/s | N32: =N31*3600*24/(150*10^6) -> 0.98537472 | O32: AU/j | Q32: AU | R32: 0.1 | S32: 1 | T32: 2 | U32: 3 | V32: 4 | W32: 5 | X32: 10 | Y32: 15 | Z32: 20
B33: Acceleration | C33: a | D33: =F33/9.81 -> 0.20183486 | E33: g | F33: =D31*10^6/(D32*10^3) -> 1.98 | G33: m/s² | I33: =I32*D32*10^-3 -> 2.5 | J33: MN | L33: distance | N33: =1/2*N31*N30*3600*24/(150*10^6) -> 4.9268736 | O33: AU | R33: =(R29-$N$33*2)/$N$32 + $N$30 * 2 -> 10.101484 | S33: =(S29-$N$33*2)/$N$32 + $N$30 * 2 -> 11.014842 | T33: =(T29-$N$33*2)/$N$32 + $N$30 * 2 -> 12.029685 | U33: =(U29-$N$33*2)/$N$32 + $N$30 * 2 -> 13.044527 | V33: =(V29-$N$33*2)/$N$32 + $N$30 * 2 -> 14.059369 | W33: =(W29-$N$33*2)/$N$32 + $N$30 * 2 -> 15.074212 | X33: =(X29-$N$33*2)/$N$32 + $N$30 * 2 -> 20.148424 | Y33: =(Y29-$N$33*2)/$N$32 + $N$30 * 2 -> 25.222635 | Z33: =(Z29-$N$33*2)/$N$32 + $N$30 * 2 -> 30.296847 | AA33: d
F34: =F33*86400*10^-3 -> 171.072 | G34: km/s/j | I34: =I33*F29 / (2*D30*10^-6) * 10^-12 -> 12.626263 | J34: TW | L34: fuel used | N34: =G35*N30 -> 85.536 | O34: % | R34: =min($N$34*2,R31) -> 17.210694 | S34: =min($N$34*2,S31) -> 54.424994 | T34: =min($N$34*2,T31) -> 76.968565 | U34: =min($N$34*2,U31) -> 94.266855 | V34: =min($N$34*2,V31) -> 108.84999 | W34: =min($N$34*2,W31) -> 121.69799 | X34: =min($N$34*2,X31) -> 171.072 | Y34: =min($N$34*2,Y31) -> 171.072 | Z34: =min($N$34*2,Z31) -> 171.072 | AA34: % fuel
A35: m = F / Ve | B35: Mass flow | C35: m | D35: =(D31*10^6)/(D29*10^3) -> 0.099 | E35: kg/s | G35: =D35*86400*10^-3 -> 8.5536 | H35: t/j
B36: Brayton cycle | D36: 35 | E36: %
B37: Waste heat | C37: h | D37: =D28*(1-D30)* (100-D36)/100 * 10^3 -> 32.5 | E37: GW = GJ/s | F37: =D37*10^3 -> 32500 | G37: GW
L38: mass ratio | N38: 1.5
B39: burn time | C39: t | D39: 0.1 | E39: s | G39: =G35/D28 -> 1.71072 | L39: Total delta v | N39: =D29*ln(N38) -> 4054.6511 | O39: km/s
B40: fuel used | C40: m | D40: =D35*D39*10^-3 -> 9.9e-06 | E40: t | I40: =I29/G35 -> 2.922746 | J40: j | N40: =N39*3600*24/(150*10^6) -> 2.335479 | O40: AU/j
B41: waste heat | C41: h | D41: =D37*D39-I23*D39 -> 3.24998 | E41: TJ
B42: speed | C42: delta v | D42: =F33*10^-3*D39 -> 0.000198 | E42: km/s | G42: =D42*24/D43 -> 0.0010527572 | H42: km/s/j
B43: time to cool | C43: cd | D43: =D41/$I$23/60/60 -> 4.5138611 | E43: h
A46: ANTIMATTER MODE
B47: Power | C47: P | D47: 5 | E47: TW | F47: =D47*10^12 -> 5000000000000
...

Sheet Batterie humaine
M2: Target mass | N2: 100 | O2: kg | S2: energy | U2: a | W2: carry
C3: Cooling : continuous 2 kW, burst 10 kW (vapor). (100 - 500 W/m²K) | L3: 5 | M3: Muscles | N3: 50 | O3: % | Q3: =N3/100*$C$18 -> 50 | R3: kg | S3: =Q3*0.02 -> 1 | T3: MW | U3: =$C$38/3*Q3/Q9 /10 -> 50 | V3: g | W3: =Q3*4-Q9 -> 100 | X3: kg
L4: 4 | M4: CPU | N4: 10 | O4: % | Q4: =N4/100*$C$18 -> 10 | R4: kg | S4: =Q4/50 -> 0.2 | T4: MW
B5: h (passive) | C5: 0.5 | D5: kW/m² K | G5: Q_conv | H5: =C5*C12*C8 -> 20 | I5: kW | J5: Q_conv = h · A · ΔT | M5: Bones | N5: 15 | O5: % | Q5: =N5/100*$C$18 -> 15 | R5: kg
B6: h (active) | C6: 1 | D6: kW/m² K | G6: Q_conv | H6: =C6*C12*C8 -> 40 | I6: kW | M6: Organs | N6: 15 | O6: % | Q6: =N6/100*$C$18 -> 15 | R6: kg
G7: structure | H7: =0.002*C12*1000 -> 4 | I7: kg | J7: 2 mm CNM | M7: Battery | N7: 10 | O7: % | Q7: =N7/100*$C$18 -> 10 | R7: kg | S7: =0.25*Q7 -> 2.5 | T7: MJ
B8: ΔT | C8: 20 | D8: K | G8: cooling | H8: =C12*4 -> 8 | I8: kg
M9: Actual | Q9: =sum(Q3:Q7) -> 100 | R9: kg
J11: 100 | K11: W | M11: Target mass | N11: 200 | O11: kg | S11: energy | U11: a | W11: carrying cap
B12: Factor | C12: 2 | H12: =C13+C14+C15+C16 -> 25 | I12: kg | J12: =100*60/1000 -> 6 | K12: kJ / min | L12: 6 | M12: Muscles | N12: 50 | O12: % | Q12: =N12/100*$N$11 -> 100 | R12: kg | S12: =Q12*0.02 -> 2 | T12: MW | U12: =$C$38/3*Q12/Q19 /10 -> 50 | V12: g | W12: =Q12*4-Q19 -> 200 | X12: kg
B13: Hardware | C13: =C12/2 -> 1 | D13: kg | F13: energy | J13: =J12*60/1000 -> 0.36 | K13: MJ / h | L13: 4 | M13: CPU | N13: 10 | O13: % | Q13: =N13/100*$N$11 -> 20 | R13: kg | S13: =Q13/50 -> 0.4 | T13: MW
B14: Water | C14: =C12*3 -> 6 | D14: kg | E14: 2500 | F14: kJ / kg | H14: =E14/1000*C14 -> 15 | I14: MJ | J14: =H15/J13 -> 14 | K14: h | M14: Bones | N14: 10 | O14: % | Q14: =N14/100*$N$11 -> 20 | R14: kg
B15: Graphene | C15: =7*C12 -> 14 | D15: kg | E15: =100*3600/1000 -> 360 | F15: kW / kg | H15: =E15/1000*C15 -> 5.04 | I15: MJ | J15: =J14*60 -> 840 | K15: min | M15: Organs | N15: 10 | O15: % | Q15: =N15/100*$N$11 -> 20 | R15: kg
B16: Fat | C16: =C12*2 -> 4 | D16: kg | E16: =10500*360/1000 -> 3780 | F16: kW / kg | H16: =E16/1000*C16 -> 15.12 | I16: MJ
M17: Battery | N17: 20 | O17: % | Q17: =N17/100*$N$11 -> 40 | R17: kg | S17: =0.25*Q17 -> 10 | T17: MJ
B18: Total mass | C18: 100 | D18: kg
B19: Muscles | C19: 50 | D19: % | F19: =C19/100*$C$18 -> 50 | G19: kg | M19: Actual | Q19: =sum(Q12:Q17) -> 200 | R19: kg
B20: CPU | C20: 10 | D20: % | F20: =C20/100*$C$18 -> 10 | G20: kg
B21: Bones | C21: 15 | D21: % | F21: =C21/100*$C$18 -> 15 | G21: kg | M21: Target mass | N21: 100 | O21: kg | S21: energy | U21: a | W21: carrying cap
B22: Organs | C22: 15 | D22: % | F22: =C22/100*$C$18 -> 15 | G22: kg | L22: 4 | M22: Muscles | N22: 50 | O22: % | Q22: =N22/100*$N$21 -> 50 | R22: kg | S22: =Q22*0.02 -> 1 | T22: MW | U22: =$C$38/3*Q22/Q28 /10 -> 33.333333 | V22: g | W22: =Q22*4-Q28 -> 50 | X22: kg
B23: Battery | C23: 20 | D23: % | F23: =C23/100*$C$18 -> 20 | G23: kg | L23: 5 | M23: CPU | N23: 50 | O23: % | Q23: =N23/100*$N$21 -> 50 | R23: kg | S23: =Q23/50 -> 1 | T23: MW
M24: Bones | N24: 15 | O24: % | Q24: =N24/100*$N$21 -> 15 | R24: kg
B25: Muscle mass | C25: =C19/100*C18 -> 50 | D25: kg | E25: athlete | M25: Organs | N25: 15 | O25: % | Q25: =N25/100*$N$21 -> 15 | R25: kg
B26: Muscles (aggro) | C26: 50 | D26: kW/kg | E26: peak | F26: 0.1 | G26: kW/kg | H26: =$C$25*C26/1000 -> 2.5 | I26: MW | M26: Battery | N26: 20 | O26: % | Q26: =N26/100*$N$21 -> 20 | R26: kg | S26: =0.25*Q26 -> 5 | T26: MJ
B27: Muscles (high) | C27: 10 | D27: kW/kg | E27: sust | F27: 0.02 | G27: kW/kg | H27: =$C$25*C27/1000 -> 0.5 | I27: MW
B28: Muscles (low) | C28: 1 | D28: kW/kg | M28: Actual | Q28: =sum(Q22:Q26) -> 150 | R28: kg
B30: CPU mass | C30: =C20/100*C18 -> 10 | D30: kg | H30: =C30*C31/1000 -> 1 | I30: MW
B31: CPU (high) | C31: 100 | D31: kW/kg | M31: Target mass | N31: 200 | O31: kg | S31: energy | U31: a | W31: carrying cap
B32: CPU (low) | C32: 1 | D32: kW/kg | L32: 5 | M32: Muscles | N32: 50 | O32: % | Q32: =N32/100*$N$31 -> 100 | R32: kg | S32: =Q32*0.02 -> 2 | T32: MW | U32: =$C$38/3*Q32/Q38 /10 -> 33.333333 | V32: g | W32: =Q32*4-Q38 -> 100 | X32: kg
L33: 6 | M33: CPU | N33: 50 | O33: % | Q33: =N33/100*$N$31 -> 100 | R33: kg | S33: =Q33/50 -> 2 | T33: MW
B34: Max discharge | C34: 1000 | D34: kW/kg | H34: =C34*C15/1000 -> 14 | I34: MW | M34: Bones | N34: 15 | O34: % | Q34: =N34/100*$N$31 -> 30 | R34: kg
M35: Organs | N35: 15 | O35: % | Q35: =N35/100*$N$31 -> 30 | R35: kg
B36: Average | C36: 1500 | D36: N/kg | M36: Battery | N36: 20 | O36: % | Q36: =N36/100*$N$31 -> 40 | R36: kg | S36: =0.25*Q36 -> 10 | T36: MJ
B37: Athletic | C37: 2000 | D37: N/kg | G37: legs | H37: =C37*C19/1000*0.3 -> 30 | I37: kN
B38: Force | C38: 3000 | D38: N/kg | G38: hold | H38: =C38*C19/9.80665/1000 -> 15.295743 | I38: t | J38: =C27*1000/C38 -> 3.3333333 | K38: m/s | M38: Actual | Q38: =sum(Q32:Q36) -> 300 | R38: kg
B39: Structure | G39: limit | H39: =H38/3 -> 5.0985811 | I39: t | J39: ARBITRARY
B41: P | C41: =F19*C27*1000 -> 500000 | D41: W | G41: Speed | H41: =(2*C41*C42 / (C43*C44))^(1/3) -> 142.87698 | I41: m/s | J41: v=​(2Pη / (ρCd​A))^1/3 | M41: Target mass | N41: 400 | O41: kg | S41: energy | U41: a | W41: carrying cap
B42: η | C42: 0.7 | D42: (efficiency) | H42: =H41*3.6 -> 514.35713 | I42: km/h | L42: 7 | M42: Muscles | N42: 50 | O42: % | Q42: =N42/100*$N$41 -> 200 | R42: kg | S42: =Q42*0.02 -> 4 | T42: MW | U42: =$C$38/3*Q42/Q48 /10 -> 50 | V42: g | W42: =Q42*4-Q48 -> 400 | X42: kg
B43: ρ | C43: 1.2 | D43: kg/m3 (air density) | L43: 5 | M43: CPU | N43: 10 | O43: % | Q43: =N43/100*$N$41 -> 40 | R43: kg | S43: =Q43/50 -> 0.8 | T43: MW
B44: CdA | C44: 0.2 | D44: m² (aerodynamism) | M44: Bones | N44: 10 | O44: % | Q44: =N44/100*$N$41 -> 40 | R44: kg
...

Sheet Augments
F2: m/s | G2: g | H2: degats | I2: % / sec | J2: Lift : body weight x | P2: kN/kg | Q2: kW/kg | R2: % corps | S2: m/s | T2: kJ
D3: Prix | E3: Indice | F3: Sprint | G3: Jump | H3: Melee | I3: Power | J3: Taille -3 | K3: Taille -2 | L3: Taille -1 | M3: Taille 0 | N3: Taille 1 | O3: Taille 2 | P3: Strength | Q3: Power | R3: Mass | S3: Swing | T3: Punch
B4: Corps | C4: Standard | D4: 0 | E4: 3 | F4: 5 | G4: 2 | H4: 0+ | I4: 0 | J4: x10 | K4: x5 | L4: x2 | M4: x1 | N4: x1 | O4: x0 | P4: 1 | Q4: 0.1 | R4: 30 | S4: 10 | T4: 0.2
C5: Athlétique | D5: 2 | E5: 4 | F5: 10 | G5: 4 | H5: 0+ | I5: 0 | J5: x20 | K5: x10 | L5: x5 | M5: x3 | N5: x2 | O5: x1 | P5: 1.5 | Q5: 0.2 | R5: 40 | S5: 20 | T5: 1
C6: Surhumain | D6: 5 | E6: 5 | F6: 20 | G6: 6 | H6: 1+ | I6: 1 | J6: x50 | K6: x20 | L6: x10 | M6: x5 | N6: x3 | O6: x2 | P6: 3 | Q6: 1 | R6: 50 | S6: 40 | T6: 5
C7: Metahumain | D7: 10 | E7: 6 | F7: 40 | G7: 10 | H7: 2+ | I7: 2 | J7: x80 | K7: x30 | L7: x15 | M7: x8 | N7: x4 | O7: x2 | P7: 6 | Q7: 2 | R7: 50 | S7: 80 | T7: 50
C8: Prototype | D8: ? | E8: 7 | F8: 50 | G8: 12 | H8: 2+ | I8: 5 | J8: x100 | K8: x40 | L8: x20 | M8: x10 | N8: x5 | O8: x3 | P8: 9 | Q8: 5 | R8: 50 | S8: 100 | T8: 100
B9: Membres | C9: Cyberlegs | D9: 3 | E9: 6 | F9: 80 | G9: 20 | H9: 2+ | I9: 1 | P9: 6 | Q9: 2 | R9: 20 | S9: 80 | T9: 64
C10: Bras Mantis | D10: 3 | E10: 6 | H10: 3+ | I10: 0.5 | J10: x10 | K10: x5 | L10: x2 | M10: x1 | N10: x1 | O10: x0 | P10: 6 | Q10: 2 | R10: 5 | S10: 200 | T10: 500
C11: Membre blindé | D11: 1 | E11: 6 | F11: 4 | G11: 1 | H11: 1+ | I11: 0.2 | J11: x0 | K11: x0 | L11: x0 | M11: x0 | N11: x0 | O11: x0 | P11: 6 | Q11: 2 | R11: 60 | S11: 10 | T11: 6
C12: Booster 'DDE' | D12: 5 | F12: +100 | G12: +10 | I12: 0 | R12: 25
B13: Externe | C13: Cyberdeck | D13: 5 | I13: 0 | R13: 20
C14: Batterie | D14: 1 | I14: x0.5 | R14: 20
B17: Standard | C17: Masse | D17: 70 | E17: kg | F17: =sum(D18:D25) -> 100 | G17: % | J17: Athlétique | K17: Masse | L17: 80 | M17: kg | N17: =sum(L18:L25) -> 100 | O17: %
B18: 3 | C18: Muscles | D18: 30 | E18: % | F18: =D18/100*D$17 -> 21 | G18: kg | J18: 4 | K18: Muscles | L18: 40 | M18: % | N18: =L18/100*L$2 -> 0 | O18: kg
C19: Cerveau | D19: 4 | E19: % | F19: =D19/100*D$17 -> 2.8 | G19: kg | K19: Cerveau | L19: 4 | M19: % | N19: =L19/100*L$2 -> 0 | O19: kg
C20: Ossature | D20: 15 | E20: % | F20: =D20/100*D$17 -> 10.5 | G20: kg | K20: Ossature | L20: 15 | M20: % | N20: =L20/100*L$2 -> 0 | O20: kg
C21: Organes | D21: 15 | E21: % | F21: =D21/100*D$17 -> 10.5 | G21: kg | K21: Organes | L21: 15 | M21: % | N21: =L21/100*L$2 -> 0 | O21: kg
B22: Batterie | C22: Hardware | D22: 0.3 | E22: % | F22: =D22/100*D$17 -> 0.21 | G22: kg | J22: Batterie | K22: Hardware | L22: 1 | M22: % | N22: =L22/100*L$2 -> 0 | O22: kg
C23: Graisse | D23: 15 | E23: % | F23: =D23/100*D$17 -> 10.5 | G23: kg | K23: Graisse | L23: 8 | M23: % | N23: =L23/100*L$2 -> 0 | O23: kg
C24: Eau | D24: 20 | E24: % | F24: =D24/100*D$17 -> 14 | G24: kg | K24: Eau | L24: 15 | M24: % | N24: =L24/100*L$2 -> 0 | O24: kg
C25: Carbs | D25: 0.7 | E25: % | F25: =D25/100*D$17 -> 0.49 | G25: kg | K25: Carbs | L25: 2 | M25: % | N25: =L25/100*L$2 -> 0 | O25: kg
B26: Transhumain | C26: Masse | D26: 90 | E26: kg | F26: =sum(D27:D34) -> 100 | G26: % | J26: Metahumain | K26: Masse | L26: 100 | M26: kg | N26: =sum(L27:L34) -> 100 | O26: %
B27: 5 | C27: Muscles | D27: 50 | E27: % | F27: =D27/100*D$11 -> 0.5 | G27: kg | J27: 6 | K27: Muscles | L27: 50 | M27: % | N27: =L27/100*L$26 -> 50 | O27: kg
C28: Cerveau | D28: 4 | E28: % | F28: =D28/100*D$11 -> 0.04 | G28: kg | K28: Cerveau | L28: 4 | M28: % | N28: =L28/100*L$26 -> 4 | O28: kg
C29: Ossature | D29: 15 | E29: % | F29: =D29/100*D$11 -> 0.15 | G29: kg | K29: Ossature | L29: 15 | M29: % | N29: =L29/100*L$26 -> 15 | O29: kg
C30: Organes | D30: 15 | E30: % | F30: =D30/100*D$11 -> 0.15 | G30: kg | K30: Organes | L30: 5 | M30: % | N30: =L30/100*L$26 -> 5 | O30: kg
B31: Batterie | C31: Hardware | D31: 1 | E31: % | F31: =D31/100*D$11 -> 0.01 | G31: kg | J31: Batterie | K31: Hardware | L31: 5 | M31: % | N31: =L31/100*L$26 -> 5 | O31: kg
C32: Graisse + | D32: 1 | E32: % | F32: =D32/100*D$11 -> 0.01 | G32: kg | K32: Graisse + | L32: 0 | M32: % | N32: =L32/100*L$26 -> 0 | O32: kg
C33: Eau | D33: 10 | E33: % | F33: =D33/100*D$11 -> 0.1 | G33: kg | K33: Eau + | L33: 13 | M33: % | N33: =L33/100*L$26 -> 13 | O33: kg
C34: Carbs + | D34: 4 | E34: % | F34: =D34/100*D$11 -> 0.04 | G34: kg | K34: Carbs + | L34: 8 | M34: % | N34: =L34/100*L$26 -> 8 | O34: kg

Sheet gravity
B3: mass | C3: 2 | D3: earth
B4: volume | C4: =F4 -> 1.2058078 | D4: earth | E4: rocky : | F4: =C3^0.27 -> 1.2058078 | G4: earth
B7: gravity | C7: =C3/(C4^2) -> 1.3755418 | D7: g

Sheet Explosives
K2: PeakOverpressure_psi | L2: PeakOverpressure_kPa | M2: Human_effects | N2: Window_glass_3mm | O2: Car_passenger | P2: Light_wood_frame_house | Q2: Brick_masonry_house | R2: Reinforced_concrete_30cm | S2: Steel_plate_5cm
B3: Energy | C3: 200000000 | D3: J | K3: 0.2 | L3: 1.4 | M3: No significant injury if sheltered; minimal structural effect | N3: Very unlikely to break | O3: No structural damage | P3: No damage | Q3: No damage | R3: No damage | S3: No damage
B4: TNT equivalent | C4: =C3/4184000 -> 47.801147 | D4: kg | K4: 0.5 | L4: 3.4 | M4: Possible eardrum rupture for some; minor debris risk | N4: Small windows may crack or pop out | O4: No structural damage; falling debris possible | P4: No damage | Q4: No damage | R4: No damage | S4: No damage
B5: W1/3TNT | C5: =C4^(1/3) -> 3.6292156 | K5: 1 | L5: 6.9 | M5: High chance of eardrum rupture; glass injuries likely | N5: Most residential windows break | O5: Localized denting or cracking | P5: Minor structural damage (doors or windows) | Q5: Minor to moderate non-structural damage | R5: Negligible | S5: No damage
G6: Z(P) | I6: distance | K6: 2 | L6: 13.8 | M6: Increased lung trauma risk; many injured from debris | N6: All standard windows shatter | O6: Possible broken windows; glass and trim ripped off | P6: Significant damage to trim and roof elements | Q6: Partial collapse of unreinforced walls possible | R6: Possible chipping or spalling | S6: No perforation
B7: light damage | C7: =I7*$C$5 -> 72.584313 | D7: m | E7: 1 psi | G7: 7 | H7: kPa | I7: 20 | J7: m | K7: 3 | L7: 20.7 | M7: High probability of serious lung injury; fatalities outdoors | N7: Commercial glazing fails | O7: Doors blown off; body intrusion possible | P7: Partial collapse of light structures | Q7: Severe structural damage to masonry | R7: Localized spalling; generally intact | S7: No perforation
B8: heavy damage | C8: =I8*$C$5 -> 29.033725 | D8: m | E8: 5 psi | G8: 35 | H8: kPa | I8: 8 | J8: m | K8: 5 | L8: 34.5 | M8: Severe injuries common; many fatalities outdoors | N8: All glazing and curtain walls fail | O8: Heavy deformation; possible rolling of vehicles | P8: Severe damage to wood-frame structures | Q8: Heavy damage; collapse of many masonry buildings | R8: Heavy spalling; thin-section breach possible | S8: No perforation
B9: severe damage | C9: =I9*$C$5 -> 18.146078 | D9: m | E9: 10 psi | G9: 70 | H9: kPa | I9: 5 | J9: m | K9: 10 | L9: 68.9 | M9: Very high lethality in the open; massive destruction | N9: Almost all glazing destroyed | O9: Vehicles overturned or crushed by debris | P9: Most wood houses destroyed | Q9: Severe structural collapse | R9: Serious RC damage; through-breaches possible | S9: No perforation; mounts may fail
K10: 20 | L10: 137.9 | M10: Essentially unsurvivable in the open; complete destruction locally | N10: Catastrophic building failure | O10: Vehicles destroyed | P10: Complete destruction of light buildings | Q10: Wide collapse of masonry | R10: Large-scale shattering or spalling | S10: No clean perforation; mounts fail
K11: 50 | L11: 344.7 | M11: Near-certain fatality; near-total obliteration | N11: Few intact structures remain | O11: Vehicles vaporized by fragments | P11: Nothing left of light buildings | Q11: Serious crushing of heavy masonry | R11: Major breach or failure of concrete | S11: Possible large plastic deformation; still unlikely to perforate
K12: 100 | L12: 689.5 | M12: Complete annihilation locally | N12: Absolute annihilation of exposed objects | O12: All vehicles destroyed | P12: All building types destroyed | Q12: Heavy damage to reinforced structures | R12: Full plastic failure of concrete | S12: Perforation depends on impulse/duration; near steel yield
K13: 1000 | L13: 6894.8 | M13: Catastrophic; extreme environment | N13: Absolute annihilation | O13: Steel and heavy structures shredded | P13: No light buildings remain | Q13: Crushing and destruction of masonry | R13: Concrete obliterated | S13: Fragment-driven penetration dominates

Sheet Stratios mass
D2: dry mass
C3: =sum(C5:C16) -> 95 | D3: 400
B5: Engine | C5: 15 | D5: =$D$3*C5/100 -> 60 | E5: 4 TW MICFAM engine
B6: Cooling | C6: 25 | D6: =$D$3*C6/100 -> 100 | E6: 3 50x20m retractable L-ETHER wings (10 GW), coolant pumps
B7: Heat sink | C7: 25 | D7: =$D$3*C7/100 -> 100 | E7: 2 TJ (Lithium hydride + L-ETHER hab wheel)
B8: Structure | C8: 10 | D8: =$D$3*C8/100 -> 40 | E8: Carbon steel hull with ceramic plating, lightweight CNT polymer internal structure
B9: Power | C9: 3 | D9: =$D$3*C9/100 -> 12 | E9: Backup fusion core, graphene capacitors and power buses
B10: Life support | C10: 3 | D10: =$D$3*C10/100 -> 12 | E10: Facilities for a military crew of 10, food and water, recycling
B11: Armor | C11: 1 | D11: =$D$3*C11/100 -> 4 | E11: Multi-layered whipple shield, front only
B12: Weapons | C12: 5 | D12: =$D$3*C12/100 -> 20 | E12: Laser turret, keel-mounted coilgun
B13: Auxiliary | C13: 3 | D13: =$D$3*C13/100 -> 12 | E13: Side thrusters, gyroscope (mounted in the hab wheel), wings and landing struts
B14: CPU | C14: 3 | D14: =$D$3*C14/100 -> 12 | E14: Bio-computer with DNA storage, autonomous AI
B15: Sensors | C15: 1 | D15: =$D$3*C15/100 -> 4 | E15: Sensors suite (radar, lidar, optical, EM sensors, internal monitoring) + Comms array
B16: Miscellaneous | C16: 1 | D16: =$D$3*C16/100 -> 4 | E16: Laser sail, land rover, repair drones and other equipment

Sheet gyro
B2: B | C2: 8 | D2: T
B3: r | C3: 1 | D3: m | E3: shaft radius
B4: A | C4: 2 | D4: m² | E4: magnetic bearing area
B6: τ max | C6: =C3 * C4*C2^2 / (8 * PI() *10^-7) * 10^-6 -> 50.929582 | D6: MN·m | E6: ring torque | G6: τmax = r⋅ B² A / 2μ0​​
B7: max Ωt​​ | C7: =C6*10^6/C10 -> 0.084882636 | D7: rad | G7: τ=L⋅Ωt​
C8: =C7*57.2958 -> 4.8634186 | D8: deg
J9: L = mrv
B10: L | C10: =C11*C12*C13 -> 600000000 | D10: kg·m²/s
B11: m | C11: 10000 | D11: kg | E11: ring mass
B12: r | C12: 30 | D12: m
B13: v | C13: 2000 | D13: m/s
B15: I | C15: =2.88*10^7 -> 28800000 | D15: kg·m² | E15: Ship moment of inertia 2.88×10^7 kg·m²
B16: Ωt​​ | C16: 0.087 | D16: rad
C17: =C16*57.2958 -> 4.9847346 | D17: deg/s
B18: ωship​ | C18: =C10*C16/C15 -> 1.8125 | D18: rad/s
C19: =C18*57.2958 -> 103.84864 | D19: deg/s
B21: P | C21: =C10*C16^2 * 10^-6 -> 4.5414 | D21: MW | E21: energy cost for torque | G21: P=LΩt²
B22: E | C22: =0.5*C11*C13^2 *10^-9 -> 20 | D22: GJ | E22: rotational energy stored | G22: E = 1/2 mv²
J23: Torque | K23: 45 | L23: MN·m
J24: F | K24: =K23* 10^6 / C3 -> 45000000 | L24: N | M24: F = Pm​*A = A * B² / 2μ0​​

Sheet Sail
K1: 1 | L1: g
K2: 63 | L2: d
E3: c= | F3: =3*10^8 -> 300000000 | G3: m/s | K3: 0.181 | L3: c
K4: 990 | L4: AU
B5: Heat res | C5: 1 | D5: TW | H5: F=(1+R)⋅P​ / c | M5: =1361*(1/0.05)^2 -> 544400 | N5: W/m² | O5: solar power at 0.05 AU
B6: Reflectivity | C6: 99.9 | D6: % | F6: =C6*10^-2 -> 0.999 | K6: 2 | L6: g | M6: =M5*10^-6 -> 0.5444 | N6: MW/m²
B7: Max laser power | C7: =1/((100-C6) * 10^-2) -> 1000 | D7: TW | H7: Where: | K7: 45 | L7: d
K8: 0.259 | L8: c | M8: =C22*10^15 / M5 -> 1836884644 | N8: m² | O8: area for 1 PW
H9: F = thrust (Newtons) | K9: 1000 | L9: AU | M9: =M8*10^-6 -> 1836.8846 | N9: km²
B10: Laser power | C10: 1 | D10: PW | F10: =C10*10^15 -> 1e+15 | G10: W | M10: =sqrt(M9) -> 42.858892 | N10: km
B11: Thrust | C11: =F11*10^-6 -> 6.6633333 | D11: MN | F11: =(1+F6)*F10 / F3 -> 6663333.3 | G11: N | H11: P = laser power (Watts) | K11: 3 | L11: g
K12: 37 | L12: d | M12: 1064 | N12: nm | O12: w = L * 1.22 * λ / D​
B13: ship mass | C13: 500 | D13: t | F13: =C13*10^3 -> 500000 | G13: kg | H13: R = reflectivity (unitless, e.g. 0.98 for 98%) | K13: 0.32 | L13: c | M13: =M12*10^-9 -> 1.064e-06 | N13: m | O13: L = w * D / ( 1.22 * λ )
B14: accel | C14: =F11/F13 -> 13.326667 | D14: m/s² | F14: =C14/9.8 -> 1.3598639 | G14: g | K14: 1000 | L14: AU | M14: =M12*10^-12 -> 1.064e-09 | N14: km | O14: w = spot size
H15: c = speed of light ≈ 3×10^8 m/s | O15: L = distance
B16: time | C16: 400 | D16: d | O16: λ = wavelength
B17: speed | C17: =C14*C16*86400/F3 -> 1.535232 | D17: c | H17: F≈1.98⋅P​ / c | O17: D = lens diameter
B18: distance | C18: =E18/(1.496*10^11) -> 53199.483 | D18: AU | E18: =1/2 *C14 * (C16*86400)^2 -> 7.95864e+15 | F18: m | G18: =C18*1.58125*10^-5 -> 0.84121683 | H18: ly
B19: aτ | C19: =C16*C14*86400 -> 460569600 | D19: m/s | E19: =C18*1.5813*10^-5 -> 0.84124343 | F19: ly
B20: v | C20: =E20/F3 -> 0.8379197 | D20: c | E20: =C19 / sqrt(1+(C19/F3)^2) -> 2.5137591e+08 | F20: m/s | J20: proper time
K21: =300*0.7 -> 210
A22: ARRAY | B22: Power | C22: 1 | D22: PW | E22: =C22*10^15 -> 1e+15 | F22: W | H22: =E22/20000 -> 50000000000 | I22: kg
B23: Radius | C23: 20 | D23: km | H23: =H22*10^-9 -> 50 | I23: Mt | L23: =60000000/20000 -> 3000 | N23: =1000000000000 / 100000000 -> 10000
B25: Spot size | C25: 1 | D25: km radius | E25: =C25*10^3 -> 1000 | F25: m
B26: Efficiency | C26: 0.5
B28: Distance | C28: =C25 * C23*2 / (1.22 * M14) / (1.496 * 10^8) -> 205.98089 | D28: AU
B29: Collector area | C29: =M9*C22 /C26 -> 3673.7693 | D29: km² | E29: =C29 * 1000000 -> 3673769287 | F29: m² | M29: full array | N29: 63500 | O29: AU
C30: =sqrt(C29) -> 60.611627 | D30: km square | N30: 60 | O30: Mt
B31: at 1g/m² | C31: =E29*10^-6 -> 3673.7693 | D31: t | G31: spacing | N31: =1.25*0.9 -> 1.125 | O31: PW
B32: Laser area | C32: =(C23*PI())^2 -> 3947.8418 | D32: km²
M33: 10% array | N33: 20000 | O33: AU
N34: 6 | O34: Mt
B35: Focus distance | C35: 65000 | D35: AU | E35: =C35 * 1.496* 10^11 -> 9.724e+15 | F35: m | G35: =C35*1.58125*10^-5 -> 1.0278125 | H35: ly | K35: =sqrt(2*E35 / C14) / 86400 -> 442.14321 | L35: days of accel | N35: 0.1 | O35: PW
B36: > lens diameter | C36: =E36*10^-3 -> 12622.53 | D36: km | E36: =1.22 * M13 * E35 / E25 -> 12622530 | F36: m | I36: D = 1.22 λ L / w | K36: =C14*K35*86400/F3 -> 1.696981 | L36: c | N36: 800 | O36: days
B37: > lens area | C37: =PI() * (C36/2)^2 -> 125136124 | D37: km² | E37: =PI() * (E36/2)^2 -> 125136124023258 | F37: m² | I37: Alens = PI * (D/2)² | N37: 0.29 | O37: c
B39: fill factor (sparse) | C39: 0.1 | K39: 20 | L39: kW/kg
B40: module area | C40: 10 | D40: m² | J40: Module power | K40: 1 | L40: kW
B41: > module count | C41: =E41 -> 1251361240233 | E41: =C39*E37 / C40 -> 1251361240233 | H41: N = Alens / (fill * Amodule) | J41: Module mass | K41: =K40/K39 -> 0.05 | L41: kg
B42: > module power | C42: =C22/E41 * 10^9 -> 0.00079912975 | D42: MW | E42: =C42*10^6 -> 799.12975 | F42: W | G42: 10% loss
C43: =C41*K41*10^-9 -> 62.568062 | D43: Mt
...

Sheet Heat 
P1: vapo
A2: HEAT SINK | C2: Metastable Lithium Hybrid | H2: LiH sensible heat | I2: 1.8 | J2: MJ/kg | M2: Li | N2: 6.94 | O2: g/mol | P2: 21 | Q2: MJ/kg | S2: LiD sensible heat | T2: 1.1 | U2: MJ/kg | X2: Li | Y2: 6.94 | Z2: g/mol | AA2: 21 | AB2: MJ/kg
H3: LiH heat of fusion | I3: 2.9 | J3: MJ/kg | M3: H | N3: 1 | O3: g/mol | S3: LiD heat of fusion | T3: 2.9 | U3: MJ/kg | X3: D | Y3: 2.014 | Z3: g/mol
B4: Decomposition | C4: 20 | D4: MJ/kg | E4: LiH > Li + 1/2 H2 decomposition is endothermic | H4: chemical decomposition | I4: =N6*N7*10^-3 -> 16.100629 | J4: MJ/kg | K4: =sum(I2:I4) -> 20.800629 | M4: H2 | N4: =N3*2 -> 2 | O4: g/mol | S4: chemical decomposition | T4: =Y6*Y7*10^-3 -> 14.518651 | U4: MJ/kg | X4: D2 | Y4: =Y3*2 -> 4.028 | Z4: g/mol
E5: Engineered for higher temp | H5: sensible heat 2000K | I5: 2.2 | J5: MJ/kg | K5: =sum(I2:I5) -> 23.000629 | M5: LiH | N5: 7.95 | O5: g/mol | S5: sensible heat 2000K | T5: 2 | U5: MJ/kg | X5: LiD | Y5: =Y2+Y3 -> 8.954 | Z5: g/mol
H6: Lithium vaporization | I6: =P2*N9 -> 18.332075 | J6: MJ/kg | K6: Latent heat of vaporization: 21 MJ/kg | M6: LiH | N6: =1000/N5 -> 125.78616 | O6: mol/kg | S6: D2 vaporization | T6: =7.8*Y10 -> 1.7544338 | U6: MJ/kg | X6: LiD | Y6: =1000/Y5 -> 111.68193 | Z6: mol/kg
B7: Vaporization | C7: 20 | D7: MJ/kg | E7: also using some dissociation/ionization energy | H7: H2 vaporization | I7: =P10*N10 -> 3.672956 | J7: MJ/kg | K7: Latent + sensible heat to 2000 K: ~445 MJ/kg | M7: ΔH | N7: 128 | O7: kJ/mol | S7: total | T7: =sum(T2:T6) -> 22.273085 | U7: MJ/kg | V7: =T11*10^6 -> 100000000 | W7: g | X7: ΔH | Y7: 130 | Z7: kJ/mol
H8: total | I8: =sum(I2:I6) -> 41.332704 | J8: MJ/kg | S8: Lithium vaporization | T8: =AA2*Y9 -> 16.276524 | U8: MJ/kg | V8: 7.95 | W8: g/mol
B9: Vapor is recaptured and ran through the Ether dust radiators to recondense | M9: Li | N9: =N2/N5 -> 0.87295597 | O9: mass ratio | S9: total | T9: =T7+T8 -> 38.549609 | U9: MJ/kg | V9: 0.5 | W9: g/mol | X9: Li | Y9: =Y2/Y5 -> 0.77507259 | Z9: mass ratio
H10: LiH mass | I10: 0.01 | J10: t | K10: =I10*10^6 -> 10000 | L10: g | M10: H2 | N10: =N3/N5 -> 0.12578616 | O10: mass ratio | P10: 29.2 | Q10: MJ/kg (vapo at 2000K) | X10: D2 | Y10: =Y3/Y5 -> 0.22492741 | Z10: mass ratio | AA10: 93 | AB10: kJ/mol
B11: Operation temp | C11: 2000 | D11: K | H11: LiH mol | I11: =K10/K11 -> 1257.8616 | J11: mol | K11: 7.95 | L11: g/mol | S11: LiH mass | T11: 100 | U11: t
H12: H2 released | I12: =I11/2 -> 628.93082 | J12: mol | K12: 0.5 | L12: g/mol | S12: LiH mol | T12: =V7/V8 -> 12578616 | U12: mol
B13: tonnage | C13: 150 | D13: t | S13: H2 released | T13: =T12/2 -> 6289308.2 | U13: mol
B14: sink | C14: =(C4)*C13*10^-3 -> 3 | D14: TJ | H14: Temp | I14: 2000 | J14: K | X14: Latent heat of vaporization: 21 MJ/kg
B15: venting | C15: =(C7)*C13*10^-3 -> 3 | D15: TJ | H15: Pressure | I15: 500 | J15: atm | S15: Temp | T15: 2000 | U15: K | X15: Latent + sensible heat to 2000 K: ~445 MJ/kg
H16: R = | I16: 0.082057 | J16: L·atm/(mol·K) | S16: Pressure | T16: 500 | U16: atm
H17: V = nRT / P | I17: =I12*0.0821*I14 / I15 -> 206.54088 | J17: L | O17: Q=m⋅[cp​⋅(Tmelt​−Tstart​)+Lf​] | S17: R = | T17: 0.082057 | U17: L·atm/(mol·K)
B18: Lithium vapor at | I18: =I17/1000 -> 0.20654088 | J18: m3 | S18: V = nRT / P | T18: =T13*0.0821*T15 / T16 -> 2065408.8 | U18: L
I19: =I18/100 -> 0.0020654088 | J19: x10x10m | O19: Q is energy stored | T19: =T18/1000 -> 2065.4088 | U19: m3
O20: m is mass | T20: =T19/100 -> 20.654088 | U20: x10x10m
O21: cp​ is specific heat (J/kg·K)
A22: COOLING | O22: Tmelt​ is melting point
B23: Ether dust tech | C23: 200 | D23: kW/m² | E23: baseline | O23: Tstart​ is starting temperature
B24: at 2000K | C24: 1 | D24: MW/m² | O24: Lf​ is latent heat of fusion (J/kg)
A26: base | B26: Structure | C26: 20 | D26: kg/m²
B27: Hardware | C27: 5 | D27: kg/m²
B28: Coolant | C28: 15 | D28: kg/m² | M28: wing
M29: 60 | N29: m
A30: high tech | B30: Wing | C30: 0.1 | D30: kg/m² | E30: CNT polymer + graphene | M30: 30 | N30: m
B31: Support structure | C31: 5 | D31: kg/m² | E31: Folding trusses/ribs, actuators & mechanisms, control surfaces | J31: =I72*M37*10^-6 -> 0.0125047 | K31: GW | L31: cloud distance | M31: 2 | N31: m | O31: =M36*10*10^-3 -> 54 | P31: t
B32: Cooling hardware | C32: 5 | D32: kg/m² | E32: Pressurized pipes, magnetic pumps, sensors | L32: top / bottom | M32: =M29*M30 -> 1800 | N32: m²
B33: Coolant | E33: > already accounted for in heat sink | I33: ROUNDED | J33: 1500 | K33: kW/m² | L33: long edge | M33: =M29*M31*2 -> 240 | N33: m²
I34: wings | J34: =J31 -> 0.0125047 | K34: GW | L34: short edge | M34: =M30*M31*2 -> 120 | N34: m²
B35: Radiator | C35: 10 | D35: kg/m² | I35: wheel | J35: =1200*J33*10^-6 -> 1.8 | K35: GW | L35: cloud surface area | M35: =M32*2+M33*2+M34 -> 4200 | N35: m²
B36: RadHull | C36: 5 | D36: kg/m² | G36: =10*10*10 -> 1000 | J36: =1200*5*10^-3 -> 6 | K36: t | L36: total wing area (3 wings) | M36: =M29*M30*3 -> 5400 | N36: m²
L37: total cloud surface (3 wings) | M37: =M35*3 -> 12600 | N37: m² | O37: =M37/M36 -> 2.3333333
I38: lithium nanodroplets (~10 nm radius):
H39: Particle mass m | I39: 1.16×10−26kg | O39: =I72*O37 -> 2.3156853
H40: Thermal velocity vth​ | I40: ~2,200 m/s (at 2000 K)
H41: Particle charge q | I41: 5.5×10−18C | O41: =2.83*664 -> 1879.12
...

Sheet Stratios laser
B2: Power density | C2: 20 | D2: kW/kg | I2: =2000*H5 -> 6000000
G3: For 10s charge + pulse
B4: Lens radius | C4: 500 | D4: m | L4: 10 sec charge
B5: Mass | C5: 10000 | D5: t | G5: Waste heat | H5: =C6*0.015 -> 3000 | I5: GJ | K5: Input power | L5: =C6*10 -> 2000000 | M5: MJ
B6: Power | C6: =C5*C2 -> 200000 | D6: MW | H6: =H5/(H9*10^3)*100 -> 62.5 | I6: % heat sink | K6: Laser heat | L6: =L5*0.3 -> 600000 | M6: MJ
B7: Efficiency | C7: 70 | D7: % | G7: Heat sink | H7: 160 | I7: t | K7: Power gen heat | L7: =L5 -> 2000000 | M7: MJ
B8: Wavelength | C8: 1064 | D8: nm | G8: Lithium+ | H8: 30 | I8: MJ / kg
H9: =(H7*10^3)*H8*10^-6 -> 4.8 | I9: TJ
C10: Lab | E10: Effective | K10: ARMOR | L10: Hull density | M10: 10 | N10: g/cm3 | O10: Ablation loss | P10: 90 | Q10: %
B11: Extreme range | C11: =(C4) / (0.0000000305 * C8) * SQRT( (0.000000002 *C6 * C7) / (0.01*C17 * PI()) ) -> 14545633 | D11: km | E11: =round((C11+C12)/200,0)*100 -> 9572700 | G11: Mostly harmless | I11: May heat up sensors or interfere with optics | L11: carbon vaporization | M11: 30 | N11: kJ/g | O11: Number of layers | P11: 2
B12: Long range | C12: =(C4) / (0.0000000305 * C8) * SQRT( (0.000000002 *C6 * C7) / (0.1*C17 * PI()) ) -> 4599732.9 | D12: km | E12: =round((C12+C13)/20,0)*10 -> 3027150 | G12: Sub-threshold burn | I12: Can damage exposed systems, weak armor | L12: CNT / graphite | M12: 100 | N12: kJ/g | O12: Energy remaining | P12: =(1-P10*0.01)^P11 *100 -> 1 | Q12: %
B13: Med range | C13: =(C4) / (0.0000000305 * C8) * SQRT( (0.000000002 *C6 * C7) / (1*C17 * PI()) ) -> 1454563.3 | D13: km | E13: =round((C13+C14)/20,0)*10 -> 957270 | G13: Matches hull resistance | I13: Burns through hull, damages one subsystem | L13: Hull heat res | M13: =M12*M10*10^-3 -> 1 | N13: MJ/cm3
B14: Short range | C14: =(C4) / (0.0000000305 * C8) * SQRT( (0.000000002 *C6 * C7) / (10*C17 * PI()) ) -> 459973.29 | D14: km | E14: =round((C14+C15)/20,0)*10 -> 302710 | G14: 10× damage threshold | I14: Punches through multiple compartments | L14: 5 cm thick | M14: =M13*5 -> 5 | N14: MJ/cm²
B15: Overkill range | C15: =(C4) / (0.0000000305 * C8) * SQRT( (0.000000002 *C6 * C7) / (100*C17 * PI()) ) -> 145456.33 | D15: km | E15: =round((C15+C16)/20,0)*10 -> 72730 | I15: Full compartment meltdown | L15: Slope, rotation, etc | M15: dice roll
B17: Hull heat res | C17: 1 | D17: MW/cm²
K19: C6 | L19: 1 | M19: 2 | N19: 3 | O19: 4 | P19: 5 | Q19: 6 | R19: 7 | S19: 8 | T19: 9 | U19: 10 | V19: 11 | W19: 12
K20: 20 | L20: =(L$19) / (0.0000000305 * $C$8) * SQRT( (0.000000002 *$K20 * $C$7) / (PI()) ) -> 29.091265 | M20: =(M$19) / (0.0000000305 * $C$8) * SQRT( (0.000000002 *$K20 * $C$7) / (PI()) ) -> 58.182531 | N20: =(N$19) / (0.0000000305 * $C$8) * SQRT( (0.000000002 *$K20 * $C$7) / (PI()) ) -> 87.273796 | O20: =(O$19) / (0.0000000305 * $C$8) * SQRT( (0.000000002 *$K20 * $C$7) / (PI()) ) -> 116.36506 | P20: =(P$19) / (0.0000000305 * $C$8) * SQRT( (0.000000002 *$K20 * $C$7) / (PI()) ) -> 145.45633 | Q20: =(Q$19) / (0.0000000305 * $C$8) * SQRT( (0.000000002 *$K20 * $C$7) / (PI()) ) -> 174.54759 | R20: =(R$19) / (0.0000000305 * $C$8) * SQRT( (0.000000002 *$K20 * $C$7) / (PI()) ) -> 203.63886 | S20: =(S$19) / (0.0000000305 * $C$8) * SQRT( (0.000000002 *$K20 * $C$7) / (PI()) ) -> 232.73012 | ... U20: =(U$19) / (0.0000000305 * $C$8) * SQRT( (0.000000002 *$K20 * $C$7) / (PI()) ) -> 290.91265
K21: 40 | L21: =(L$19) / (0.0000000305 * $C$8) * SQRT( (0.000000002 *$K21 * $C$7) / (PI()) ) -> 41.141262 | M21: =(M$19) / (0.0000000305 * $C$8) * SQRT( (0.000000002 *$K21 * $C$7) / (PI()) ) -> 82.282524 | N21: =(N$19) / (0.0000000305 * $C$8) * SQRT( (0.000000002 *$K21 * $C$7) / (PI()) ) -> 123.42379 | O21: =(O$19) / (0.0000000305 * $C$8) * SQRT( (0.000000002 *$K21 * $C$7) / (PI()) ) -> 164.56505 | P21: =(P$19) / (0.0000000305 * $C$8) * SQRT( (0.000000002 *$K21 * $C$7) / (PI()) ) -> 205.70631 | Q21: =(Q$19) / (0.0000000305 * $C$8) * SQRT( (0.000000002 *$K21 * $C$7) / (PI()) ) -> 246.84757 | R21: =(R$19) / (0.0000000305 * $C$8) * SQRT( (0.000000002 *$K21 * $C$7) / (PI()) ) -> 287.98883 | S21: =(S$19) / (0.0000000305 * $C$8) * SQRT( (0.000000002 *$K21 * $C$7) / (PI()) ) -> 329.1301 | ... U21: =(U$19) / (0.0000000305 * $C$8) * SQRT( (0.000000002 *$K21 * $C$7) / (PI()) ) -> 411.41262
H22: =H9*10^3/H5/6/60 -> 0.0044444444 | I22: h of continuous fire | K22: 60 | L22: =(L$19) / (0.0000000305 * $C$8) * SQRT( (0.000000002 *$K22 * $C$7) / (PI()) ) -> 50.38755 | M22: =(M$19) / (0.0000000305 * $C$8) * SQRT( (0.000000002 *$K22 * $C$7) / (PI()) ) -> 100.7751 | N22: =(N$19) / (0.0000000305 * $C$8) * SQRT( (0.000000002 *$K22 * $C$7) / (PI()) ) -> 151.16265 | O22: =(O$19) / (0.0000000305 * $C$8) * SQRT( (0.000000002 *$K22 * $C$7) / (PI()) ) -> 201.5502 | P22: =(P$19) / (0.0000000305 * $C$8) * SQRT( (0.000000002 *$K22 * $C$7) / (PI()) ) -> 251.93775 | Q22: =(Q$19) / (0.0000000305 * $C$8) * SQRT( (0.000000002 *$K22 * $C$7) / (PI()) ) -> 302.3253 | R22: =(R$19) / (0.0000000305 * $C$8) * SQRT( (0.000000002 *$K22 * $C$7) / (PI()) ) -> 352.71285 | S22: =(S$19) / (0.0000000305 * $C$8) * SQRT( (0.000000002 *$K22 * $C$7) / (PI()) ) -> 403.1004 | ... U22: =(U$19) / (0.0000000305 * $C$8) * SQRT( (0.000000002 *$K22 * $C$7) / (PI()) ) -> 503.8755
K23: 80 | L23: =(L$19) / (0.0000000305 * $C$8) * SQRT( (0.000000002 *$K23 * $C$7) / (PI()) ) -> 58.182531 | M23: =(M$19) / (0.0000000305 * $C$8) * SQRT( (0.000000002 *$K23 * $C$7) / (PI()) ) -> 116.36506 | N23: =(N$19) / (0.0000000305 * $C$8) * SQRT( (0.000000002 *$K23 * $C$7) / (PI()) ) -> 174.54759 | O23: =(O$19) / (0.0000000305 * $C$8) * SQRT( (0.000000002 *$K23 * $C$7) / (PI()) ) -> 232.73012 | P23: =(P$19) / (0.0000000305 * $C$8) * SQRT( (0.000000002 *$K23 * $C$7) / (PI()) ) -> 290.91265 | Q23: =(Q$19) / (0.0000000305 * $C$8) * SQRT( (0.000000002 *$K23 * $C$7) / (PI()) ) -> 349.09518 | R23: =(R$19) / (0.0000000305 * $C$8) * SQRT( (0.000000002 *$K23 * $C$7) / (PI()) ) -> 407.27772 | S23: =(S$19) / (0.0000000305 * $C$8) * SQRT( (0.000000002 *$K23 * $C$7) / (PI()) ) -> 465.46025 | ... U23: =(U$19) / (0.0000000305 * $C$8) * SQRT( (0.000000002 *$K23 * $C$7) / (PI()) ) -> 581.82531
K24: 100 | L24: =(L$19) / (0.0000000305 * $C$8) * SQRT( (0.000000002 *$K24 * $C$7) / (PI()) ) -> 65.050047 | M24: =(M$19) / (0.0000000305 * $C$8) * SQRT( (0.000000002 *$K24 * $C$7) / (PI()) ) -> 130.10009 | N24: =(N$19) / (0.0000000305 * $C$8) * SQRT( (0.000000002 *$K24 * $C$7) / (PI()) ) -> 195.15014 | O24: =(O$19) / (0.0000000305 * $C$8) * SQRT( (0.000000002 *$K24 * $C$7) / (PI()) ) -> 260.20019 | P24: =(P$19) / (0.0000000305 * $C$8) * SQRT( (0.000000002 *$K24 * $C$7) / (PI()) ) -> 325.25023 | Q24: =(Q$19) / (0.0000000305 * $C$8) * SQRT( (0.000000002 *$K24 * $C$7) / (PI()) ) -> 390.30028 | R24: =(R$19) / (0.0000000305 * $C$8) * SQRT( (0.000000002 *$K24 * $C$7) / (PI()) ) -> 455.35033 | S24: =(S$19) / (0.0000000305 * $C$8) * SQRT( (0.000000002 *$K24 * $C$7) / (PI()) ) -> 520.40038 | ... U24: =(U$19) / (0.0000000305 * $C$8) * SQRT( (0.000000002 *$K24 * $C$7) / (PI()) ) -> 650.50047
K25: 120 | L25: =(L$19) / (0.0000000305 * $C$8) * SQRT( (0.000000002 *$K25 * $C$7) / (PI()) ) -> 71.258756 | M25: =(M$19) / (0.0000000305 * $C$8) * SQRT( (0.000000002 *$K25 * $C$7) / (PI()) ) -> 142.51751 | N25: =(N$19) / (0.0000000305 * $C$8) * SQRT( (0.000000002 *$K25 * $C$7) / (PI()) ) -> 213.77627 | O25: =(O$19) / (0.0000000305 * $C$8) * SQRT( (0.000000002 *$K25 * $C$7) / (PI()) ) -> 285.03502 | P25: =(P$19) / (0.0000000305 * $C$8) * SQRT( (0.000000002 *$K25 * $C$7) / (PI()) ) -> 356.29378 | Q25: =(Q$19) / (0.0000000305 * $C$8) * SQRT( (0.000000002 *$K25 * $C$7) / (PI()) ) -> 427.55254 | R25: =(R$19) / (0.0000000305 * $C$8) * SQRT( (0.000000002 *$K25 * $C$7) / (PI()) ) -> 498.81129 | S25: =(S$19) / (0.0000000305 * $C$8) * SQRT( (0.000000002 *$K25 * $C$7) / (PI()) ) -> 570.07005 | ... U25: =(U$19) / (0.0000000305 * $C$8) * SQRT( (0.000000002 *$K25 * $C$7) / (PI()) ) -> 712.58756
